[2024-04-28T19:13:14.570+0000] {local_task_job_runner.py:120} INFO - ::group::Pre task execution logs
[2024-04-28T19:13:14.590+0000] {taskinstance.py:2073} INFO - Dependencies all met for dep_context=non-requeueable deps ti=<TaskInstance: dag_yellow_cab.download_file manual__2024-04-28T19:13:12.804895+00:00 [queued]>
[2024-04-28T19:13:14.598+0000] {taskinstance.py:2073} INFO - Dependencies all met for dep_context=requeueable deps ti=<TaskInstance: dag_yellow_cab.download_file manual__2024-04-28T19:13:12.804895+00:00 [queued]>
[2024-04-28T19:13:14.599+0000] {taskinstance.py:2303} INFO - Starting attempt 1 of 1
[2024-04-28T19:13:14.612+0000] {taskinstance.py:2327} INFO - Executing <Task(PythonOperator): download_file> on 2024-04-28 19:13:12.804895+00:00
[2024-04-28T19:13:14.617+0000] {warnings.py:110} WARNING - /home/***/.local/lib/python3.12/site-packages/***/task/task_runner/standard_task_runner.py:61: DeprecationWarning: This process (pid=398) is multi-threaded, use of fork() may lead to deadlocks in the child.
  pid = os.fork()

[2024-04-28T19:13:14.619+0000] {standard_task_runner.py:63} INFO - Started process 399 to run task
[2024-04-28T19:13:14.619+0000] {standard_task_runner.py:90} INFO - Running: ['***', 'tasks', 'run', 'dag_yellow_cab', 'download_file', 'manual__2024-04-28T19:13:12.804895+00:00', '--job-id', '52', '--raw', '--subdir', 'DAGS_FOLDER/data_pipeline_cab.py', '--cfg-path', '/tmp/tmpqzwgl_gv']
[2024-04-28T19:13:14.621+0000] {standard_task_runner.py:91} INFO - Job 52: Subtask download_file
[2024-04-28T19:13:14.665+0000] {task_command.py:426} INFO - Running <TaskInstance: dag_yellow_cab.download_file manual__2024-04-28T19:13:12.804895+00:00 [running]> on host 3b50846985b8
[2024-04-28T19:13:14.754+0000] {taskinstance.py:2644} INFO - Exporting env vars: AIRFLOW_CTX_DAG_OWNER='***' AIRFLOW_CTX_DAG_ID='dag_yellow_cab' AIRFLOW_CTX_TASK_ID='download_file' AIRFLOW_CTX_EXECUTION_DATE='2024-04-28T19:13:12.804895+00:00' AIRFLOW_CTX_TRY_NUMBER='1' AIRFLOW_CTX_DAG_RUN_ID='manual__2024-04-28T19:13:12.804895+00:00'
[2024-04-28T19:13:14.755+0000] {taskinstance.py:430} INFO - ::endgroup::
[2024-04-28T19:13:14.772+0000] {_universal.py:514} INFO - Request URL: 'https://azureyellowcab.blob.core.windows.net/cabfiles?restype=REDACTED&comp=REDACTED'
Request method: 'GET'
Request headers:
    'x-ms-version': 'REDACTED'
    'Accept': 'application/xml'
    'User-Agent': 'azsdk-python-storage-blob/12.19.1 Python/3.12.2 (Linux-6.6.22-linuxkit-x86_64-with-glibc2.36)'
    'x-ms-date': 'REDACTED'
    'x-ms-client-request-id': '5cd72efa-0593-11ef-ba00-0242c0a81004'
    'Authorization': 'REDACTED'
No body was attached to the request
[2024-04-28T19:13:15.214+0000] {_universal.py:550} INFO - Response status: 200
Response headers:
    'Transfer-Encoding': 'chunked'
    'Content-Type': 'application/xml'
    'Server': 'Windows-Azure-Blob/1.0 Microsoft-HTTPAPI/2.0'
    'x-ms-request-id': 'e9cbf67f-a01e-000d-1ea0-99004b000000'
    'x-ms-client-request-id': '5cd72efa-0593-11ef-ba00-0242c0a81004'
    'x-ms-version': 'REDACTED'
    'Date': 'Sun, 28 Apr 2024 19:13:15 GMT'
[2024-04-28T19:13:15.219+0000] {logging_mixin.py:188} INFO - join() argument must be str, bytes, or os.PathLike object, not 'BlobProperties'
[2024-04-28T19:13:15.219+0000] {logging_mixin.py:188} INFO - An error occurred: Download not compleated correctly
[2024-04-28T19:13:15.220+0000] {taskinstance.py:441} INFO - ::group::Post task execution logs
[2024-04-28T19:13:15.222+0000] {taskinstance.py:2890} ERROR - Task failed with exception
Traceback (most recent call last):
  File "/opt/airflow/dags/scripts/scripts.py", line 29, in get_file
    with open(file=os.path.join(SOURCE_FILE_PATH, filename), mode="wb") as sample_blob:
                   ^^^^^^^^^^^^^^^^^^^^^^^^^^^^^^^^^^^^^^^^
  File "<frozen posixpath>", line 90, in join
  File "<frozen genericpath>", line 164, in _check_arg_types
TypeError: join() argument must be str, bytes, or os.PathLike object, not 'BlobProperties'

During handling of the above exception, another exception occurred:

Traceback (most recent call last):
  File "/opt/airflow/dags/scripts/scripts.py", line 19, in file_download
    get_file(filename)
  File "/opt/airflow/dags/scripts/scripts.py", line 35, in get_file
    raise AirflowFailException('Download not compleated correctly')
airflow.exceptions.AirflowFailException: Download not compleated correctly

During handling of the above exception, another exception occurred:

Traceback (most recent call last):
  File "/home/airflow/.local/lib/python3.12/site-packages/airflow/models/taskinstance.py", line 465, in _execute_task
    result = _execute_callable(context=context, **execute_callable_kwargs)
             ^^^^^^^^^^^^^^^^^^^^^^^^^^^^^^^^^^^^^^^^^^^^^^^^^^^^^^^^^^^^^
  File "/home/airflow/.local/lib/python3.12/site-packages/airflow/models/taskinstance.py", line 432, in _execute_callable
    return execute_callable(context=context, **execute_callable_kwargs)
           ^^^^^^^^^^^^^^^^^^^^^^^^^^^^^^^^^^^^^^^^^^^^^^^^^^^^^^^^^^^^
  File "/home/airflow/.local/lib/python3.12/site-packages/airflow/models/baseoperator.py", line 400, in wrapper
    return func(self, *args, **kwargs)
           ^^^^^^^^^^^^^^^^^^^^^^^^^^^
  File "/home/airflow/.local/lib/python3.12/site-packages/airflow/operators/python.py", line 235, in execute
    return_value = self.execute_callable()
                   ^^^^^^^^^^^^^^^^^^^^^^^
  File "/home/airflow/.local/lib/python3.12/site-packages/airflow/operators/python.py", line 252, in execute_callable
    return self.python_callable(*self.op_args, **self.op_kwargs)
           ^^^^^^^^^^^^^^^^^^^^^^^^^^^^^^^^^^^^^^^^^^^^^^^^^^^^^
  File "/opt/airflow/dags/scripts/scripts.py", line 22, in file_download
    raise AirflowFailException('ERROR')
airflow.exceptions.AirflowFailException: ERROR
[2024-04-28T19:13:15.239+0000] {taskinstance.py:1205} INFO - Immediate failure requested. Marking task as FAILED. dag_id=dag_yellow_cab, task_id=download_file, execution_date=20240428T191312, start_date=20240428T191314, end_date=20240428T191315
[2024-04-28T19:13:15.259+0000] {standard_task_runner.py:110} ERROR - Failed to execute job 52 for task download_file (ERROR; 399)
[2024-04-28T19:13:15.291+0000] {local_task_job_runner.py:240} INFO - Task exited with return code 1
[2024-04-28T19:13:15.316+0000] {taskinstance.py:3482} INFO - 0 downstream tasks scheduled from follow-on schedule check
[2024-04-28T19:13:15.320+0000] {local_task_job_runner.py:222} INFO - ::endgroup::
