[2024-04-28T19:18:17.946+0000] {local_task_job_runner.py:120} INFO - ::group::Pre task execution logs
[2024-04-28T19:18:17.969+0000] {taskinstance.py:2073} INFO - Dependencies all met for dep_context=non-requeueable deps ti=<TaskInstance: dag_yellow_cab.validate_file manual__2024-04-28T19:17:46.740631+00:00 [queued]>
[2024-04-28T19:18:17.977+0000] {taskinstance.py:2073} INFO - Dependencies all met for dep_context=requeueable deps ti=<TaskInstance: dag_yellow_cab.validate_file manual__2024-04-28T19:17:46.740631+00:00 [queued]>
[2024-04-28T19:18:17.978+0000] {taskinstance.py:2303} INFO - Starting attempt 1 of 1
[2024-04-28T19:18:17.992+0000] {taskinstance.py:2327} INFO - Executing <Task(BranchPythonOperator): validate_file> on 2024-04-28 19:17:46.740631+00:00
[2024-04-28T19:18:17.997+0000] {warnings.py:110} WARNING - /home/***/.local/lib/python3.12/site-packages/***/task/task_runner/standard_task_runner.py:61: DeprecationWarning: This process (pid=465) is multi-threaded, use of fork() may lead to deadlocks in the child.
  pid = os.fork()

[2024-04-28T19:18:17.999+0000] {standard_task_runner.py:63} INFO - Started process 466 to run task
[2024-04-28T19:18:17.999+0000] {standard_task_runner.py:90} INFO - Running: ['***', 'tasks', 'run', 'dag_yellow_cab', 'validate_file', 'manual__2024-04-28T19:17:46.740631+00:00', '--job-id', '54', '--raw', '--subdir', 'DAGS_FOLDER/data_pipeline_cab.py', '--cfg-path', '/tmp/tmptn01yk2g']
[2024-04-28T19:18:18.002+0000] {standard_task_runner.py:91} INFO - Job 54: Subtask validate_file
[2024-04-28T19:18:18.044+0000] {task_command.py:426} INFO - Running <TaskInstance: dag_yellow_cab.validate_file manual__2024-04-28T19:17:46.740631+00:00 [running]> on host 3b50846985b8
[2024-04-28T19:18:18.134+0000] {taskinstance.py:2644} INFO - Exporting env vars: AIRFLOW_CTX_DAG_OWNER='***' AIRFLOW_CTX_DAG_ID='dag_yellow_cab' AIRFLOW_CTX_TASK_ID='validate_file' AIRFLOW_CTX_EXECUTION_DATE='2024-04-28T19:17:46.740631+00:00' AIRFLOW_CTX_TRY_NUMBER='1' AIRFLOW_CTX_DAG_RUN_ID='manual__2024-04-28T19:17:46.740631+00:00'
[2024-04-28T19:18:18.135+0000] {taskinstance.py:430} INFO - ::endgroup::
[2024-04-28T19:18:18.149+0000] {baseoperator.py:399} WARNING - BranchPythonOperator.execute cannot be called outside TaskInstance!
[2024-04-28T19:18:18.149+0000] {python.py:237} INFO - Done. Returned value was: None
[2024-04-28T19:18:18.150+0000] {branch.py:36} INFO - Branch into None
[2024-04-28T19:18:18.151+0000] {skipmixin.py:178} INFO - Following branch None
[2024-04-28T19:18:18.159+0000] {skipmixin.py:246} INFO - Skipping tasks [('file_exception', -1)]
[2024-04-28T19:18:18.180+0000] {taskinstance.py:441} INFO - ::group::Post task execution logs
[2024-04-28T19:18:18.188+0000] {taskinstance.py:1205} INFO - Marking task as SUCCESS. dag_id=dag_yellow_cab, task_id=validate_file, execution_date=20240428T191746, start_date=20240428T191817, end_date=20240428T191818
[2024-04-28T19:18:18.221+0000] {local_task_job_runner.py:240} INFO - Task exited with return code 0
[2024-04-28T19:18:18.239+0000] {taskinstance.py:3482} INFO - 0 downstream tasks scheduled from follow-on schedule check
[2024-04-28T19:18:18.241+0000] {local_task_job_runner.py:222} INFO - ::endgroup::
