[2024-04-28T18:40:35.659+0000] {local_task_job_runner.py:120} INFO - ::group::Pre task execution logs
[2024-04-28T18:40:35.685+0000] {taskinstance.py:2073} INFO - Dependencies all met for dep_context=non-requeueable deps ti=<TaskInstance: dag_yellow_cab.validate_file manual__2024-04-28T18:40:32.105313+00:00 [queued]>
[2024-04-28T18:40:35.693+0000] {taskinstance.py:2073} INFO - Dependencies all met for dep_context=requeueable deps ti=<TaskInstance: dag_yellow_cab.validate_file manual__2024-04-28T18:40:32.105313+00:00 [queued]>
[2024-04-28T18:40:35.694+0000] {taskinstance.py:2303} INFO - Starting attempt 1 of 1
[2024-04-28T18:40:35.707+0000] {taskinstance.py:2327} INFO - Executing <Task(BranchPythonOperator): validate_file> on 2024-04-28 18:40:32.105313+00:00
[2024-04-28T18:40:35.712+0000] {warnings.py:110} WARNING - /home/***/.local/lib/python3.12/site-packages/***/task/task_runner/standard_task_runner.py:61: DeprecationWarning: This process (pid=94) is multi-threaded, use of fork() may lead to deadlocks in the child.
  pid = os.fork()

[2024-04-28T18:40:35.714+0000] {standard_task_runner.py:63} INFO - Started process 95 to run task
[2024-04-28T18:40:35.714+0000] {standard_task_runner.py:90} INFO - Running: ['***', 'tasks', 'run', 'dag_yellow_cab', 'validate_file', 'manual__2024-04-28T18:40:32.105313+00:00', '--job-id', '39', '--raw', '--subdir', 'DAGS_FOLDER/data_pipeline_cab.py', '--cfg-path', '/tmp/tmpqee4h327']
[2024-04-28T18:40:35.716+0000] {standard_task_runner.py:91} INFO - Job 39: Subtask validate_file
[2024-04-28T18:40:35.765+0000] {task_command.py:426} INFO - Running <TaskInstance: dag_yellow_cab.validate_file manual__2024-04-28T18:40:32.105313+00:00 [running]> on host 7608059f513e
[2024-04-28T18:40:35.861+0000] {taskinstance.py:2644} INFO - Exporting env vars: AIRFLOW_CTX_DAG_OWNER='***' AIRFLOW_CTX_DAG_ID='dag_yellow_cab' AIRFLOW_CTX_TASK_ID='validate_file' AIRFLOW_CTX_EXECUTION_DATE='2024-04-28T18:40:32.105313+00:00' AIRFLOW_CTX_TRY_NUMBER='1' AIRFLOW_CTX_DAG_RUN_ID='manual__2024-04-28T18:40:32.105313+00:00'
[2024-04-28T18:40:35.862+0000] {taskinstance.py:430} INFO - ::endgroup::
[2024-04-28T18:40:35.876+0000] {baseoperator.py:399} WARNING - BranchPythonOperator.execute cannot be called outside TaskInstance!
[2024-04-28T18:40:35.877+0000] {python.py:237} INFO - Done. Returned value was: None
[2024-04-28T18:40:35.878+0000] {branch.py:36} INFO - Branch into None
[2024-04-28T18:40:35.878+0000] {skipmixin.py:178} INFO - Following branch None
[2024-04-28T18:40:35.887+0000] {skipmixin.py:246} INFO - Skipping tasks [('file_exception', -1)]
[2024-04-28T18:40:35.906+0000] {taskinstance.py:441} INFO - ::group::Post task execution logs
[2024-04-28T18:40:35.914+0000] {taskinstance.py:1205} INFO - Marking task as SUCCESS. dag_id=dag_yellow_cab, task_id=validate_file, execution_date=20240428T184032, start_date=20240428T184035, end_date=20240428T184035
[2024-04-28T18:40:35.937+0000] {local_task_job_runner.py:240} INFO - Task exited with return code 0
[2024-04-28T18:40:35.953+0000] {taskinstance.py:3482} INFO - 0 downstream tasks scheduled from follow-on schedule check
[2024-04-28T18:40:35.955+0000] {local_task_job_runner.py:222} INFO - ::endgroup::
